<?xml version="1.0" ?>

<!--
Copyright (c) 2009-2013, A. Hornung, University of Freiburg
All rights reserved.

Redistribution and use in source and binary forms, with or without
modification, are permitted provided that the following conditions are met:

    * Redistributions of source code must retain the above copyright
      notice, this list of conditions and the following disclaimer.
    * Redistributions in binary form must reproduce the above copyright
      notice, this list of conditions and the following disclaimer in the
      documentation and/or other materials provided with the distribution.
    * Neither the name of the University of Freiburg nor the names of its
      contributors may be used to endorse or promote products derived from
      this software without specific prior written permission.

THIS SOFTWARE IS PROVIDED BY THE COPYRIGHT HOLDERS AND CONTRIBUTORS "AS IS"
AND ANY EXPRESS OR IMPLIED WARRANTIES, INCLUDING, BUT NOT LIMITED TO, THE
IMPLIED WARRANTIES OF MERCHANTABILITY AND FITNESS FOR A PARTICULAR PURPOSE
ARE DISCLAIMED. IN NO EVENT SHALL THE COPYRIGHT OWNER OR CONTRIBUTORS BE
LIABLE FOR ANY DIRECT, INDIRECT, INCIDENTAL, SPECIAL, EXEMPLARY, OR
CONSEQUENTIAL DAMAGES (INCLUDING, BUT NOT LIMITED TO, PROCUREMENT OF
SUBSTITUTE GOODS OR SERVICES; LOSS OF USE, DATA, OR PROFITS; OR BUSINESS
INTERRUPTION) HOWEVER CAUSED AND ON ANY THEORY OF LIABILITY, WHETHER IN
CONTRACT, STRICT LIABILITY, OR TORT (INCLUDING NEGLIGENCE OR OTHERWISE)
ARISING IN ANY WAY OUT OF THE USE OF THIS SOFTWARE, EVEN IF ADVISED OF THE
POSSIBILITY OF SUCH DAMAGE.
-->

<!-- =================================================================================== -->
<!-- |    This document was autogenerated by xacro from nao_robot.xacro                | -->
<!-- |    EDITING THIS FILE BY HAND IS NOT RECOMMENDED                                 | -->
<!-- =================================================================================== -->
<!--******************************************************************
 ****** File automatically generated by generate_urdf.py script ******
 *********************************************************************-->
<robot name="NaoH25V50" xmlns:xacro="http://www.ros.org/wiki/xacro">
  <joint name="HeadYaw" type="revolute">
    <parent link="torso"/>
    <child link="neck"/>
    <origin rpy="0 0 0" xyz="0 0 0.1265"/>
    <axis xyz="0 0 1.0"/>
    <limit effort="1.547" lower="-2.08567" upper="2.08567" velocity="8.26797"/>
  </joint>
  <link name="neck">
    <inertial>
      <mass value="0.07842"/>
      <inertia ixx="1.60324e-05" ixy="1.57e-09" ixz="3.16276e-09" iyy="1.70394e-05" iyz="-5.295e-08" izz="5.53372e-06"/>
      <origin rpy="0 0 0" xyz="-1e-05 0 -0.02742"/>
    </inertial>
    <visual>
      <geometry>
        <mesh filename="../meshes/V40/HeadYaw.dae" scale="0.1 0.1 0.1"/>
      </geometry>
      <origin rpy="0 0 0" xyz="0 0 0"/>
    </visual>
    <collision>
      <geometry>
        <mesh filename="../meshes/V40/HeadYaw_0.10.stl" scale="0.1 0.1 0.1"/>
      </geometry>
      <origin rpy="0 0 0" xyz="0 0 0"/>
    </collision>
  </link>
  <joint name="HeadPitch" type="revolute">
    <parent link="neck"/>
    <child link="head"/>
    <origin rpy="0 0 0" xyz="0 0 0"/>
    <axis xyz="0 1.0 0"/>
    <limit effort="1.532" lower="-0.671952" upper="0.514872" velocity="7.19407"/>
  </joint>
  <link name="head">
    <inertial>
      <mass value="0.60533"/>
      <inertia ixx="0.000957766" ixy="8.78814e-06" ixz="5.33702e-06" iyy="0.000816836" iyz="-2.99579e-05" izz="0.000984976"/>
      <origin rpy="0 0 0" xyz="-0.00112 0 0.05258"/>
    </inertial>
    <visual>
      <geometry>
        <mesh filename="../meshes/V40/HeadPitch.dae" scale="0.1 0.1 0.1"/>
      </geometry>
      <origin rpy="0 0 0" xyz="0 0 0"/>
    </visual>
    <collision>
      <geometry>
        <mesh filename="../meshes/V40/HeadPitch_0.10.stl" scale="0.1 0.1 0.1"/>
      </geometry>
      <origin rpy="0 0 0" xyz="0 0 0"/>
    </collision>
  </link>
  <joint name="LHipYawPitch" type="revolute">
    <parent link="torso"/>
    <child link="l_pelvis"/>
    <origin rpy="0 0 0" xyz="0 0.05 -0.085"/>
    <axis xyz="0 0.707106 -0.707106"/>
    <limit effort="3.348" lower="-1.14529" upper="0.740718" velocity="4.16174"/>
  </joint>
  <link name="l_pelvis">
    <inertial>
      <mass value="0.06981"/>
      <inertia ixx="2.3407e-05" ixy="1.07922e-06" ixz="-1.76003e-06" iyy="4.76355e-05" iyz="2.76058e-06" izz="4.97021e-05"/>
      <origin rpy="0 0 0" xyz="-0.00781 -0.01114 0.02661"/>
    </inertial>
    <visual>
      <geometry>
        <mesh filename="../meshes/V40/LHipYawPitch.dae" scale="0.1 0.1 0.1"/>
      </geometry>
      <origin rpy="0 0 0" xyz="0 0 0"/>
    </visual>
    <collision>
      <geometry>
        <mesh filename="../meshes/V40/LHipYawPitch_0.10.stl" scale="0.1 0.1 0.1"/>
      </geometry>
      <origin rpy="0 0 0" xyz="0 0 0"/>
    </collision>
  </link>
  <joint name="LHipRoll" type="revolute">
    <parent link="l_pelvis"/>
    <child link="l_hip"/>
    <origin rpy="0 0 0" xyz="0 0 0"/>
    <axis xyz="1.0 0 0"/>
    <limit effort="3.348" lower="-0.379435" upper="0.79046" velocity="4.16174"/>
  </joint>
  <link name="l_hip">
    <inertial>
      <mass value="0.14053"/>
      <inertia ixx="2.38445e-05" ixy="-6.53605e-07" ixz="7.12893e-06" iyy="6.08246e-05" iyz="-2.14072e-07" izz="5.43691e-05"/>
      <origin rpy="0 0 0" xyz="-0.01549 0.00029 -0.00515"/>
    </inertial>
    <visual>
      <geometry>
        <mesh filename="../meshes/V40/LHipRoll.dae" scale="0.1 0.1 0.1"/>
      </geometry>
      <origin rpy="0 0 0" xyz="0 0 0"/>
    </visual>
    <collision>
      <geometry>
        <mesh filename="../meshes/V40/LHipRoll_0.10.stl" scale="0.1 0.1 0.1"/>
      </geometry>
      <origin rpy="0 0 0" xyz="0 0 0"/>
    </collision>
  </link>
  <joint name="LHipPitch" type="revolute">
    <parent link="l_hip"/>
    <child link="l_thigh"/>
    <origin rpy="0 0 0" xyz="0 0 0"/>
    <axis xyz="0 1.0 0"/>
    <limit effort="3.023" lower="-1.53589" upper="0.48398" velocity="6.40239"/>
  </joint>
  <link name="l_thigh">
    <inertial>
      <mass value="0.38968"/>
      <inertia ixx="0.000509844" ixy="2.11296e-06" ixz="5.64129e-05" iyy="0.000465358" iyz="-7.91029e-06" izz="0.000301098"/>
      <origin rpy="0 0 0" xyz="0.00138 0.00221 -0.05373"/>
    </inertial>
    <visual>
      <geometry>
        <mesh filename="../meshes/V40/LHipPitch.dae" scale="0.1 0.1 0.1"/>
      </geometry>
      <origin rpy="0 0 0" xyz="0 0 0"/>
    </visual>
    <collision>
      <geometry>
        <mesh filename="../meshes/V40/LHipPitch_0.10.stl" scale="0.1 0.1 0.1"/>
      </geometry>
      <origin rpy="0 0 0" xyz="0 0 0"/>
    </collision>
  </link>
  <joint name="LKneePitch" type="revolute">
    <parent link="l_thigh"/>
    <child link="l_tibia"/>
    <origin rpy="0 0 0" xyz="0 0 -0.1"/>
    <axis xyz="0 1.0 0"/>
    <limit effort="3.023" lower="-0.0923279" upper="2.11255" velocity="6.40239"/>
  </joint>
  <link name="l_tibia">
    <inertial>
      <mass value="0.30142"/>
      <inertia ixx="0.000446171" ixy="3.70584e-06" ixz="-3.09008e-05" iyy="0.000388084" iyz="6.01953e-06" izz="0.000185516"/>
      <origin rpy="0 0 0" xyz="0.00453 0.00225 -0.04936"/>
    </inertial>
    <visual>
      <geometry>
        <mesh filename="../meshes/V40/LKneePitch.dae" scale="0.1 0.1 0.1"/>
      </geometry>
      <origin rpy="0 0 0" xyz="0 0 0"/>
    </visual>
    <collision>
      <geometry>
        <mesh filename="../meshes/V40/LKneePitch_0.10.stl" scale="0.1 0.1 0.1"/>
      </geometry>
      <origin rpy="0 0 0" xyz="0 0 0"/>
    </collision>
  </link>
  <joint name="LAnklePitch" type="revolute">
    <parent link="l_tibia"/>
    <child link="l_ankle_pitch"/>
    <origin rpy="0 0 0" xyz="0 0 -0.1029"/>
    <axis xyz="0 1.0 0"/>
    <limit effort="3.023" lower="-1.18944" upper="0.922581" velocity="6.40239"/>
  </joint>
  <link name="l_ankle_pitch">
    <inertial>
      <mass value="0.13416"/>
      <inertia ixx="3.22034e-05" ixy="-8.83212e-09" ixz="4.27549e-06" iyy="6.7943e-05" iyz="2.84849e-07" izz="5.48269e-05"/>
      <origin rpy="0 0 0" xyz="0.00045 0.00029 0.00685"/>
    </inertial>
    <visual>
      <geometry>
        <mesh filename="../meshes/V40/LAnklePitch.dae" scale="0.1 0.1 0.1"/>
      </geometry>
      <origin rpy="0 0 0" xyz="0 0 0"/>
    </visual>
    <collision>
      <geometry>
        <mesh filename="../meshes/V40/LAnklePitch_0.10.stl" scale="0.1 0.1 0.1"/>
      </geometry>
      <origin rpy="0 0 0" xyz="0 0 0"/>
    </collision>
  </link>
  <joint name="LAnkleRoll" type="revolute">
    <parent link="l_ankle_pitch"/>
    <child link="l_ankle"/>
    <origin rpy="0 0 0" xyz="0 0 0"/>
    <axis xyz="1.0 0 0"/>
    <limit effort="3.348" lower="-0.397761" upper="0.768992" velocity="4.16174"/>
  </joint>
  <link name="l_ankle">
    <inertial>
      <mass value="0.17184"/>
      <inertia ixx="8.72911e-05" ixy="8.71925e-06" ixz="-2.10563e-06" iyy="0.000353024" iyz="3.73459e-07" izz="0.000412846"/>
      <origin rpy="0 0 0" xyz="0.02542 0.0033 -0.03239"/>
    </inertial>
    <visual>
      <geometry>
        <mesh filename="../meshes/V40/LAnkleRoll.dae" scale="0.1 0.1 0.1"/>
      </geometry>
      <origin rpy="0 0 0" xyz="0 0 0"/>
    </visual>
    <collision>
      <geometry>
        <mesh filename="../meshes/V40/LAnkleRoll_0.10.stl" scale="0.1 0.1 0.1"/>
      </geometry>
      <origin rpy="0 0 0" xyz="0 0 0"/>
    </collision>
  </link>
  <joint name="LLeg_effector_fixedjoint" type="fixed">
    <parent link="l_ankle"/>
    <child link="l_sole"/>
    <origin rpy="0 0 0" xyz="0 0 -0.04511"/>
    <axis xyz="0 0 0"/>
  </joint>
  <link name="l_sole"/>
  <joint name="LLeg_toe_in_fixedjoint" type="fixed">
    <parent link="l_ankle"/>
    <child link="l_toe_in"/>
    <origin rpy="0 0 0" xyz="0.08 -0.03 -0.04511"/>
    <axis xyz="0 0 0"/>
  </joint>
  <link name="l_toe_in"/>
  <joint name="LLeg_toe_out_fixedjoint" type="fixed">
    <parent link="l_ankle"/>
    <child link="l_toe_out"/>
    <origin rpy="0 0 0" xyz="0.08 0.03 -0.04511"/>
    <axis xyz="0 0 0"/>
  </joint>
  <link name="l_toe_out"/>
  <joint name="LLeg_heel_in_fixedjoint" type="fixed">
    <parent link="l_ankle"/>
    <child link="l_heel_in"/>
    <origin rpy="0 0 0" xyz="-0.04 -0.03 -0.04511"/>
    <axis xyz="0 0 0"/>
  </joint>
  <link name="l_heel_in"/>
  <joint name="LLeg_heel_out_fixedjoint" type="fixed">
    <parent link="l_ankle"/>
    <child link="l_heel_out"/>
    <origin rpy="0 0 0" xyz="-0.04 0.03 -0.04511"/>
    <axis xyz="0 0 0"/>
  </joint>
  <link name="l_heel_out"/>
  <joint name="RHipYawPitch" type="revolute">
    <parent link="torso"/>
    <child link="r_pelvis"/>
    <origin rpy="0 0 0" xyz="0 -0.05 -0.085"/>
    <axis xyz="0 0.707106 0.707106"/>
    <limit effort="3.348" lower="-1.14529" upper="0.740718" velocity="4.16174"/>
    <mimic joint="LHipYawPitch" multiplier="1.0" offset="0"/>
  </joint>
  <link name="r_pelvis">
    <inertial>
      <mass value="0.06981"/>
      <inertia ixx="3.18766e-05" ixy="-1.07152e-06" ixz="-1.77295e-06" iyy="5.18361e-05" iyz="-7.00664e-06" izz="5.39657e-05"/>
      <origin rpy="0 0 0" xyz="-0.00781 0.01114 0.02661"/>
    </inertial>
    <visual>
      <geometry>
        <mesh filename="../meshes/V40/RHipYawPitch.dae" scale="0.1 0.1 0.1"/>
      </geometry>
      <origin rpy="0 0 0" xyz="0 0 0"/>
    </visual>
    <collision>
      <geometry>
        <mesh filename="../meshes/V40/RHipYawPitch_0.10.stl" scale="0.1 0.1 0.1"/>
      </geometry>
      <origin rpy="0 0 0" xyz="0 0 0"/>
    </collision>
  </link>
  <joint name="RHipRoll" type="revolute">
    <parent link="r_pelvis"/>
    <child link="r_hip"/>
    <origin rpy="0 0 0" xyz="0 0 0"/>
    <axis xyz="1.0 0 0"/>
    <limit effort="3.348" lower="-0.79046" upper="0.379435" velocity="4.16174"/>
  </joint>
  <link name="r_hip">
    <inertial>
      <mass value="0.14053"/>
      <inertia ixx="2.38475e-05" ixy="6.12085e-07" ixz="7.10235e-06" iyy="6.0824e-05" iyz="2.12392e-07" izz="5.43727e-05"/>
      <origin rpy="0 0 0" xyz="-0.01549 -0.00029 -0.00515"/>
    </inertial>
    <visual>
      <geometry>
        <mesh filename="../meshes/V40/RHipRoll.dae" scale="0.1 0.1 0.1"/>
      </geometry>
      <origin rpy="0 0 0" xyz="0 0 0"/>
    </visual>
    <collision>
      <geometry>
        <mesh filename="../meshes/V40/RHipRoll_0.10.stl" scale="0.1 0.1 0.1"/>
      </geometry>
      <origin rpy="0 0 0" xyz="0 0 0"/>
    </collision>
  </link>
  <joint name="RHipPitch" type="revolute">
    <parent link="r_hip"/>
    <child link="r_thigh"/>
    <origin rpy="0 0 0" xyz="0 0 0"/>
    <axis xyz="0 1.0 0"/>
    <limit effort="3.0226" lower="-1.53589" upper="0.48398" velocity="6.40239"/>
  </joint>
  <link name="r_thigh">
    <inertial>
      <mass value="0.38968"/>
      <inertia ixx="0.000510607" ixy="-2.02799e-06" ixz="5.69893e-05" iyy="0.0004665" iyz="7.09563e-06" izz="0.000301333"/>
      <origin rpy="0 0 0" xyz="0.00138 -0.00221 -0.05373"/>
    </inertial>
    <visual>
      <geometry>
        <mesh filename="../meshes/V40/RHipPitch.dae" scale="0.1 0.1 0.1"/>
      </geometry>
      <origin rpy="0 0 0" xyz="0 0 0"/>
    </visual>
    <collision>
      <geometry>
        <mesh filename="../meshes/V40/RHipPitch_0.10.stl" scale="0.1 0.1 0.1"/>
      </geometry>
      <origin rpy="0 0 0" xyz="0 0 0"/>
    </collision>
  </link>
  <joint name="RKneePitch" type="revolute">
    <parent link="r_thigh"/>
    <child link="r_tibia"/>
    <origin rpy="0 0 0" xyz="0 0 -0.1"/>
    <axis xyz="0 1.0 0"/>
    <limit effort="3.0226" lower="-0.0923279" upper="2.11255" velocity="6.40239"/>
  </joint>
  <link name="r_tibia">
    <inertial>
      <mass value="0.30142"/>
      <inertia ixx="0.000446921" ixy="-3.96872e-06" ixz="-3.94009e-05" iyy="0.000387711" iyz="-5.00034e-06" izz="0.000183741"/>
      <origin rpy="0 0 0" xyz="0.00453 -0.00225 -0.04936"/>
    </inertial>
    <visual>
      <geometry>
        <mesh filename="../meshes/V40/RKneePitch.dae" scale="0.1 0.1 0.1"/>
      </geometry>
      <origin rpy="0 0 0" xyz="0 0 0"/>
    </visual>
    <collision>
      <geometry>
        <mesh filename="../meshes/V40/RKneePitch_0.10.stl" scale="0.1 0.1 0.1"/>
      </geometry>
      <origin rpy="0 0 0" xyz="0 0 0"/>
    </collision>
  </link>
  <joint name="RAnklePitch" type="revolute">
    <parent link="r_tibia"/>
    <child link="r_ankle_pitch"/>
    <origin rpy="0 0 0" xyz="0 0 -0.1029"/>
    <axis xyz="0 1.0 0"/>
    <limit effort="3.0226" lower="-1.1863" upper="0.932006" velocity="6.40239"/>
  </joint>
  <link name="r_ankle_pitch">
    <inertial>
      <mass value="0.13416"/>
      <inertia ixx="3.22017e-05" ixy="4.68321e-08" ixz="4.28821e-06" iyy="6.79885e-05" iyz="-2.71089e-07" izz="5.48747e-05"/>
      <origin rpy="0 0 0" xyz="0.00045 -0.00029 0.00685"/>
    </inertial>
    <visual>
      <geometry>
        <mesh filename="../meshes/V40/RAnklePitch.dae" scale="0.1 0.1 0.1"/>
      </geometry>
      <origin rpy="0 0 0" xyz="0 0 0"/>
    </visual>
    <collision>
      <geometry>
        <mesh filename="../meshes/V40/RAnklePitch_0.10.stl" scale="0.1 0.1 0.1"/>
      </geometry>
      <origin rpy="0 0 0" xyz="0 0 0"/>
    </collision>
  </link>
  <joint name="RAnkleRoll" type="revolute">
    <parent link="r_ankle_pitch"/>
    <child link="r_ankle"/>
    <origin rpy="0 0 0" xyz="0 0 0"/>
    <axis xyz="1.0 0 0"/>
    <limit effort="3.348" lower="-0.768992" upper="0.397761" velocity="4.16174"/>
  </joint>
  <link name="r_ankle">
    <inertial>
      <mass value="0.17184"/>
      <inertia ixx="8.71513e-05" ixy="-8.53992e-06" ixz="-2.35184e-06" iyy="0.000352156" iyz="-4.81708e-07" izz="0.000412125"/>
      <origin rpy="0 0 0" xyz="0.02542 -0.0033 -0.03239"/>
    </inertial>
    <visual>
      <geometry>
        <mesh filename="../meshes/V40/RAnkleRoll.dae" scale="0.1 0.1 0.1"/>
      </geometry>
      <origin rpy="0 0 0" xyz="0 0 0"/>
    </visual>
    <collision>
      <geometry>
        <mesh filename="../meshes/V40/RAnkleRoll_0.10.stl" scale="0.1 0.1 0.1"/>
      </geometry>
      <origin rpy="0 0 0" xyz="0 0 0"/>
    </collision>
  </link>
  <joint name="RLeg_effector_fixedjoint" type="fixed">
    <parent link="r_ankle"/>
    <child link="r_sole"/>
    <origin rpy="0 0 0" xyz="0 0 -0.04511"/>
    <axis xyz="0 0 0"/>
  </joint>
  <link name="r_sole"/>
  <joint name="RLeg_toe_in_fixedjoint" type="fixed">
    <parent link="r_ankle"/>
    <child link="r_toe_in"/>
    <origin rpy="0 0 0" xyz="0.08 0.03 -0.04511"/>
    <axis xyz="0 0 0"/>
  </joint>
  <link name="r_toe_in"/>
  <joint name="RLeg_toe_out_fixedjoint" type="fixed">
    <parent link="r_ankle"/>
    <child link="r_toe_out"/>
    <origin rpy="0 0 0" xyz="0.08 -0.03 -0.04511"/>
    <axis xyz="0 0 0"/>
  </joint>
  <link name="r_toe_out"/>
  <joint name="RLeg_heel_in_fixedjoint" type="fixed">
    <parent link="r_ankle"/>
    <child link="r_heel_in"/>
    <origin rpy="0 0 0" xyz="-0.04 0.03 -0.04511"/>
    <axis xyz="0 0 0"/>
  </joint>
  <link name="r_heel_in"/>
  <joint name="RLeg_heel_out_fixedjoint" type="fixed">
    <parent link="r_ankle"/>
    <child link="r_heel_out"/>
    <origin rpy="0 0 0" xyz="-0.04 -0.03 -0.04511"/>
    <axis xyz="0 0 0"/>
  </joint>
  <link name="r_heel_out"/>
  <link name="base_link"/>
  <joint name="base_link_fixedjoint" type="fixed">
    <parent link="base_link"/>
    <child link="torso"/>
    <origin rpy="0 0 0" xyz="0 0 0"/>
    <axis xyz="0 0 0"/>
  </joint>
  <link name="torso">
    <inertial>
      <mass value="1.04956"/>
      <inertia ixx="0.00308361" ixy="1.43116e-05" ixz="-3.30211e-05" iyy="0.0028835" iyz="-2.70793e-05" izz="0.0015924"/>
      <origin rpy="0 0 0" xyz="-0.00413 0 0.04342"/>
    </inertial>
    <visual>
      <geometry>
        <mesh filename="../meshes/V40/Torso.dae" scale="0.1 0.1 0.1"/>
      </geometry>
      <origin rpy="0 0 0" xyz="0 0 0"/>
    </visual>
    <collision>
      <geometry>
        <mesh filename="../meshes/V40/Torso_0.10.stl" scale="0.1 0.1 0.1"/>
      </geometry>
      <origin rpy="0 0 0" xyz="0 0 0"/>
    </collision>
  </link>
  <joint name="LShoulderPitch" type="revolute">
    <parent link="torso"/>
    <child link="l_shoulder"/>
    <origin rpy="0 0 0" xyz="0 0.098 0.1"/>
    <axis xyz="0 1.0 0"/>
    <limit effort="1.329" lower="-2.08567" upper="2.08567" velocity="8.26797"/>
  </joint>
  <link name="l_shoulder">
    <inertial>
      <mass value="0.09304"/>
      <inertia ixx="1.83025e-05" ixy="2.06011e-06" ixz="1.88776e-09" iyy="1.39005e-05" iyz="-3.66592e-07" izz="2.01862e-05"/>
      <origin rpy="0 0 0" xyz="-0.00165 -0.02663 0.00014"/>
    </inertial>
    <visual>
      <geometry>
        <mesh filename="../meshes/V40/LShoulderPitch.dae" scale="0.1 0.1 0.1"/>
      </geometry>
      <origin rpy="0 0 0" xyz="0 0 0"/>
    </visual>
    <collision>
      <geometry>
        <mesh filename="../meshes/V40/LShoulderPitch_0.10.stl" scale="0.1 0.1 0.1"/>
      </geometry>
      <origin rpy="0 0 0" xyz="0 0 0"/>
    </collision>
  </link>
  <joint name="LShoulderRoll" type="revolute">
    <parent link="l_shoulder"/>
    <child link="l_bicep"/>
    <origin rpy="0 0 0" xyz="0 0 0"/>
    <axis xyz="0 0 1.0"/>
    <limit effort="1.7835" lower="-0.314159" upper="1.32645" velocity="7.19407"/>
  </joint>
  <link name="l_bicep">
    <inertial>
      <mass value="0.15777"/>
      <inertia ixx="8.7181e-05" ixy="-2.53381e-05" ixz="-1.4213e-05" iyy="0.000274712" iyz="4.71439e-07" izz="0.000241812"/>
      <origin rpy="0 0 0" xyz="0.02455 0.00563 0.0033"/>
    </inertial>
    <visual>
      <geometry>
        <mesh filename="../meshes/V40/LShoulderRoll.dae" scale="0.1 0.1 0.1"/>
      </geometry>
      <origin rpy="0 0 0" xyz="0 0 0"/>
    </visual>
    <collision>
      <geometry>
        <mesh filename="../meshes/V40/LShoulderRoll_0.10.stl" scale="0.1 0.1 0.1"/>
      </geometry>
      <origin rpy="0 0 0" xyz="0 0 0"/>
    </collision>
  </link>
  <joint name="LElbowYaw" type="revolute">
    <parent link="l_bicep"/>
    <child link="l_elbow"/>
    <origin rpy="0 0 0" xyz="0.105 0.015 0"/>
    <axis xyz="1.0 0 0"/>
    <limit effort="1.547" lower="-2.08567" upper="2.08567" velocity="8.26797"/>
  </joint>
  <link name="l_elbow">
    <inertial>
      <mass value="0.06483"/>
      <inertia ixx="5.59588e-06" ixy="4.21e-09" ixz="2.92241e-07" iyy="2.66179e-05" iyz="-1.84e-09" izz="2.76294e-05"/>
      <origin rpy="0 0 0" xyz="-0.02744 0 -0.00014"/>
    </inertial>
  </link>
  <joint name="LElbowRoll" type="revolute">
    <parent link="l_elbow"/>
    <child link="l_fore_arm"/>
    <origin rpy="0 0 0" xyz="0 0 0"/>
    <axis xyz="0 0 1.0"/>
    <limit effort="1.532" lower="-1.54462" upper="-0.0349066" velocity="7.19407"/>
  </joint>
  <link name="l_fore_arm">
    <inertial>
      <mass value="0.07761"/>
      <inertia ixx="2.46746e-05" ixy="3.23152e-06" ixz="1.58221e-06" iyy="3.83837e-05" iyz="1.39194e-07" izz="3.59708e-05"/>
      <origin rpy="0 0 0" xyz="0.02556 0.00281 0.00076"/>
    </inertial>
    <visual>
      <geometry>
        <mesh filename="../meshes/V40/LElbowRoll.dae" scale="0.1 0.1 0.1"/>
      </geometry>
      <origin rpy="0 0 0" xyz="0 0 0"/>
    </visual>
    <collision>
      <geometry>
        <mesh filename="../meshes/V40/LElbowRoll_0.10.stl" scale="0.1 0.1 0.1"/>
      </geometry>
      <origin rpy="0 0 0" xyz="0 0 0"/>
    </collision>
  </link>
  <joint name="LWristYaw" type="revolute">
    <parent link="l_fore_arm"/>
    <child link="l_wrist"/>
    <origin rpy="0 0 0" xyz="0.05595 0 0"/>
    <axis xyz="1.0 0 0"/>
    <limit effort="0.4075" lower="-1.82387" upper="1.82387" velocity="24.6229"/>
  </joint>
  <link name="l_wrist">
    <inertial>
      <mass value="0.18533"/>
      <inertia ixx="6.86477e-05" ixy="1.15465e-07" ixz="-2.87254e-06" iyy="0.000135756" iyz="2.67539e-06" izz="0.000133228"/>
      <origin rpy="0 0 0" xyz="0.03434 -0.00088 0.00308"/>
    </inertial>
    <visual>
      <geometry>
        <mesh filename="../meshes/V40/LWristYaw.dae" scale="0.1 0.1 0.1"/>
      </geometry>
      <origin rpy="0 0 0" xyz="0 0 0"/>
    </visual>
    <collision>
      <geometry>
        <mesh filename="../meshes/V40/LWristYaw_0.10.stl" scale="0.1 0.1 0.1"/>
      </geometry>
      <origin rpy="0 0 0" xyz="0 0 0"/>
    </collision>
  </link>
  <joint name="LHand" type="revolute">
    <parent link="l_wrist"/>
    <child link="l_gripper"/>
    <origin rpy="0 0 0" xyz="0.05775 0 -0.01231"/>
    <axis xyz="1.0 0 0"/>
    <limit effort="0.292" lower="0" upper="1.0" velocity="8.33"/>
  </joint>
  <link name="l_gripper">
    <inertial>
      <mass value="2e-06"/>
      <inertia ixx="1.1e-09" ixy="0" ixz="0" iyy="1.1e-09" iyz="0" izz="1.1e-09"/>
    </inertial>
  </link>
  <joint name="RShoulderPitch" type="revolute">
    <parent link="torso"/>
    <child link="r_shoulder"/>
    <origin rpy="0 0 0" xyz="0 -0.098 0.1"/>
    <axis xyz="0 1.0 0"/>
    <limit effort="1.329" lower="-2.08567" upper="2.08567" velocity="8.26797"/>
  </joint>
  <link name="r_shoulder">
    <inertial>
      <mass value="0.09304"/>
      <inertia ixx="1.83025e-05" ixy="-2.06011e-06" ixz="1.88776e-09" iyy="1.39005e-05" iyz="3.66592e-07" izz="2.01862e-05"/>
      <origin rpy="0 0 0" xyz="-0.00165 0.02663 0.00014"/>
    </inertial>
    <visual>
      <geometry>
        <mesh filename="../meshes/V40/RShoulderPitch.dae" scale="0.1 0.1 0.1"/>
      </geometry>
      <origin rpy="0 0 0" xyz="0 0 0"/>
    </visual>
    <collision>
      <geometry>
        <mesh filename="../meshes/V40/RShoulderPitch_0.10.stl" scale="0.1 0.1 0.1"/>
      </geometry>
      <origin rpy="0 0 0" xyz="0 0 0"/>
    </collision>
  </link>
  <joint name="RShoulderRoll" type="revolute">
    <parent link="r_shoulder"/>
    <child link="r_bicep"/>
    <origin rpy="0 0 0" xyz="0 0 0"/>
    <axis xyz="0 0 1.0"/>
    <limit effort="1.783" lower="-1.32645" upper="0.314159" velocity="7.19407"/>
  </joint>
  <link name="r_bicep">
    <inertial>
      <mass value="0.15777"/>
      <inertia ixx="0.000103401" ixy="5.48849e-05" ixz="-1.32643e-05" iyy="0.00027077" iyz="9.16707e-06" izz="0.000254529"/>
      <origin rpy="0 0 0" xyz="0.02455 -0.00563 0.0033"/>
    </inertial>
    <visual>
      <geometry>
        <mesh filename="../meshes/V40/RShoulderRoll.dae" scale="0.1 0.1 0.1"/>
      </geometry>
      <origin rpy="0 0 0" xyz="0 0 0"/>
    </visual>
    <collision>
      <geometry>
        <mesh filename="../meshes/V40/RShoulderRoll_0.10.stl" scale="0.1 0.1 0.1"/>
      </geometry>
      <origin rpy="0 0 0" xyz="0 0 0"/>
    </collision>
  </link>
  <joint name="RElbowYaw" type="revolute">
    <parent link="r_bicep"/>
    <child link="r_elbow"/>
    <origin rpy="0 0 0" xyz="0.105 -0.015 0"/>
    <axis xyz="1.0 0 0"/>
    <limit effort="1.547" lower="-2.08567" upper="2.08567" velocity="8.26797"/>
  </joint>
  <link name="r_elbow">
    <inertial>
      <mass value="0.06483"/>
      <inertia ixx="5.59588e-06" ixy="4.21e-09" ixz="2.92241e-07" iyy="2.66179e-05" iyz="-1.84e-09" izz="2.76294e-05"/>
      <origin rpy="0 0 0" xyz="-0.02744 0 -0.00014"/>
    </inertial>
  </link>
  <joint name="RElbowRoll" type="revolute">
    <parent link="r_elbow"/>
    <child link="r_fore_arm"/>
    <origin rpy="0 0 0" xyz="0 0 0"/>
    <axis xyz="0 0 1.0"/>
    <limit effort="1.532" lower="0.0349066" upper="1.54462" velocity="7.19407"/>
  </joint>
  <link name="r_fore_arm">
    <inertial>
      <mass value="0.07761"/>
      <inertia ixx="2.47331e-05" ixy="-3.2418e-06" ixz="9.06451e-07" iyy="3.84719e-05" iyz="-1.38804e-07" izz="3.59319e-05"/>
      <origin rpy="0 0 0" xyz="0.02556 -0.00281 0.00076"/>
    </inertial>
    <visual>
      <geometry>
        <mesh filename="../meshes/V40/RElbowRoll.dae" scale="0.1 0.1 0.1"/>
      </geometry>
      <origin rpy="0 0 0" xyz="0 0 0"/>
    </visual>
    <collision>
      <geometry>
        <mesh filename="../meshes/V40/RElbowRoll_0.10.stl" scale="0.1 0.1 0.1"/>
      </geometry>
      <origin rpy="0 0 0" xyz="0 0 0"/>
    </collision>
  </link>
  <joint name="RWristYaw" type="revolute">
    <parent link="r_fore_arm"/>
    <child link="r_wrist"/>
    <origin rpy="0 0 0" xyz="0.05595 0 0"/>
    <axis xyz="1.0 0 0"/>
    <limit effort="0.4075" lower="-1.82387" upper="1.82387" velocity="24.6229"/>
  </joint>
  <link name="r_wrist">
    <inertial>
      <mass value="0.18533"/>
      <inertia ixx="6.86477e-05" ixy="1.13165e-05" ixz="-2.87254e-06" iyy="0.000135756" iyz="3.68003e-06" izz="0.000133228"/>
      <origin rpy="0 0 0" xyz="0.03434 0.00088 0.00308"/>
    </inertial>
    <visual>
      <geometry>
        <mesh filename="../meshes/V40/RWristYaw.dae" scale="0.1 0.1 0.1"/>
      </geometry>
      <origin rpy="0 0 0" xyz="0 0 0"/>
    </visual>
    <collision>
      <geometry>
        <mesh filename="../meshes/V40/RWristYaw_0.10.stl" scale="0.1 0.1 0.1"/>
      </geometry>
      <origin rpy="0 0 0" xyz="0 0 0"/>
    </collision>
  </link>
  <joint name="RHand" type="revolute">
    <parent link="r_wrist"/>
    <child link="r_gripper"/>
    <origin rpy="0 0 0" xyz="0.05775 0 -0.01213"/>
    <axis xyz="1.0 0 0"/>
    <limit effort="0.292" lower="0" upper="1.0" velocity="8.33"/>
  </joint>
  <link name="r_gripper">
    <inertial>
      <mass value="2e-06"/>
      <inertia ixx="1.1e-09" ixy="0" ixz="0" iyy="1.1e-09" iyz="0" izz="1.1e-09"/>
    </inertial>
  </link>
  <link name="CameraBottom_optical_frame"/>
  <joint name="CameraBottom_optical_frame_fixedjoint" type="fixed">
    <parent link="CameraBottom_frame"/>
    <child link="CameraBottom_optical_frame"/>
    <origin rpy="-1.57079632679 0 -1.57079632679" xyz="0 0 0"/>
  </joint>
  <link name="CameraBottom_frame"/>
  <joint name="CameraBottom_sensor_fixedjoint" type="fixed">
    <parent link="head"/>
    <child link="CameraBottom_frame"/>
    <origin rpy="0 0.692896 0" xyz="0.05071 0 0.01774"/>
    <axis xyz="0 0 0"/>
  </joint>
  <link name="CameraTop_frame"/>
  <joint name="CameraTop_sensor_fixedjoint" type="fixed">
    <parent link="head"/>
    <child link="CameraTop_frame"/>
    <origin rpy="0 0.0209435 0" xyz="0.05871 0 0.06364"/>
    <axis xyz="0 0 0"/>
  </joint>
  <link name="CameraTop_optical_frame"/>
  <joint name="CameraTop_optical_frame_fixedjoint" type="fixed">
    <parent link="CameraTop_frame"/>
    <child link="CameraTop_optical_frame"/>
    <origin rpy="-1.57079632679 0 -1.57079632679" xyz="0 0 0"/>
  </joint>
</robot>